Workbook

Sheet VALORES
B3: VALORES DE CUMPLIMIENTO | F3: VALORES DE NIVEL
B4: % De cumplimiento | C4: Detalle | F4: % De cumplimiento | G4: NIVEL
B5: 0 | C5: No documentado / No existente | F5: 0% - 24% | G5: INICIAL
B6: 0.25 | C6: Aplicado / No documentado | F6: 25% - 49% | G6: NOVATO
B7: 0.5 | C7: Documentado / No aplicado | F7: 50%- 74% | G7: COMPETENTE
B8: 0.75 | C8: Aplicado y documentado | F8: 75%- 99% | G8: AVANZADO
B9: 1 | C9: Aplicado, documentado y controlado | F9: 1 | G9: EXPERTO
B10: N/A | C10: No aplica

Sheet REQUISITOS
A1: ANÁLISIS DEL GRADO DE IMPLEMENTACIÓN DE LA NORMA ISO 14001:2026
A3: EMPRESA:
A5: FECHA APLICACIÓN:
A7: RESPONSABLE:
A8: Modo de uso: Con el texto de la norma ISO 14001:2026 en mano y para cada punto normativo, responda con total honestidad marcando con una X si cumple totalmente o parcialmente el requisito y de un % conforme a los valores de cumplimiento. Puede agregar un comentario para justificar su evaluación. En las demás hojas de calculo se mostrara la brecha en forma visual y los análisis por numeral de la norma.
A12: 4. Contexto de la organización
A13: 4.1 Comprensión de la organización y de su contexto
A14: La organización debe: | B14: 0 | C14: 0.25 | D14: 0.5 | E14: 0.75 | F14: 1 | G14: N/A | H14: Observaciones
A15: Determinar las cuestiones externas e internas pertinentes para su propósito y que afectan su capacidad para lograr los resultados previstos del sistema de gestión ambiental.
A16: Considerar las condiciones ambientales que pueden afectar a la organización o verse afectadas por sus actividades, productos y servicios.
A17: Considerar, cuando sea pertinente, factores como contaminación, disponibilidad de recursos naturales, cambio climático, biodiversidad y salud de los ecosistemas.
A18: Utilizar la información del contexto para planificar, implementar, mantener y mejorar el sistema de gestión ambiental.
A19: 4.2 Comprensión de las necesidades y expectativas de las partes interesadas
A20: La organización debe: | B20: 0 | C20: 0.25 | D20: X | E20: 0.75 | F20: 1 | G20: N/A | H20: Observaciones
A21: Determinar las partes interesadas pertinentes para el sistema de gestión ambiental.
A22: Determinar las necesidades y expectativas pertinentes de dichas partes interesadas.
A23: Determinar cuáles de estas necesidades y expectativas se convierten en obligaciones de compliance.
A24: Determinar cuáles obligaciones de compliance serán abordadas mediante el sistema de gestión ambiental.
A25: Considerar, cuando corresponda, necesidades y expectativas relacionadas con contaminación, recursos naturales, cambio climático, biodiversidad o ecosistemas.
A26: 4.3 Determinación del alcance de un sistema de gestión ambiental
A27: La organización debe: | B27: 0 | C27: 0.25 | D27: 0.5 | E27: X | F27: 1 | G27: N/A | H27: Observaciones
A28: Determinar los límites y la aplicabilidad del sistema de gestión ambiental para establecer su alcance.
A29: Considerar las cuestiones externas e internas, las obligaciones de compliance, las unidades, funciones y límites físicos de la organización.
A30: Considerar las actividades, productos, servicios y la capacidad de ejercer control o influencia a lo largo de su ciclo de vida.
A31: Incluir dentro del sistema de gestión ambiental todas las actividades, productos y servicios que se encuentren dentro del alcance definido.
A32: Mantener el alcance disponible como información documentada y ponerlo a disposición de las partes interesadas.
A33: 4.4 Sistema de gestión ambiental
A34: La organización debe: | B34: 0 | C34: 0.25 | D34: 0.5 | E34: 0.75 | F34: 1 | G34: N/A | H34: Observaciones
A35: Establecer, implementar, mantener y mejorar continuamente un sistema de gestión ambiental que incluya los procesos necesarios y sus interacciones.
A36: Asegurar que el sistema de gestión ambiental permita lograr los resultados previstos, incluida la mejora del desempeño ambiental.
A37: Considerar el conocimiento obtenido sobre el contexto y las partes interesadas al establecer y mantener el sistema de gestión ambiental.
A38: 5. Liderazgo
A39: 5.1 Liderazgo y compromiso
A40: La alta dirección debe: | B40: 0 | C40: 0.25 | D40: 0.5 | E40: 0.75 | F40: 1 | G40: N/A | H40: Observaciones
A41: Asumir la rendición de cuentas por la eficacia del sistema de gestión ambiental y asegurar que logre sus resultados previstos.
A42: Asegurar que la política, los objetivos y los requisitos del sistema de gestión ambiental se integren con la dirección estratégica, el contexto y los procesos de negocio.
A43: Asegurar la disponibilidad de los recursos necesarios para el sistema de gestión ambiental.
A44: Comunicar la importancia de la gestión ambiental, dirigir y apoyar a las personas, y promover la mejora continua.
A45: 5.2 Política ambiental
A46: La alta dirección debe: | B46: 0 | C46: 0.25 | D46: 0.5 | E46: 0.75 | F46: 1 | G46: N/A | H46: Observaciones
...

Sheet ANÁLISIS DATOS GLOBAL
B2: ANÁLISIS DE INFORMACIÓN
B4: TU NIVEL DE IMPLEMENTACIÓN GENERAL | L4: =N16 -> INICIAL
B7: 4. CONTEXTO DE LA ORGANIZACIÓN | L7: % IMPLEMENTACIÓN POR CLÁUSULA
B8: NUMERAL | C8: 0 | D8: 0.25 | E8: 0.5 | F8: 0.75 | G8: 1 | H8: N/A | I8: TOTALES | L8: CLÁUSULA | M8: % DE IMPLEMENTACIÓN | N8: NIVEL
B9: 4.1 | C9: =COUNTA(REQUISITOS!B15:B18) -> 0 | D9: =COUNTA(REQUISITOS!C15:C18) -> 0 | E9: =COUNTA(REQUISITOS!D15:D18) -> 0 | F9: =COUNTA(REQUISITOS!E15:E18) -> 0 | G9: =COUNTA(REQUISITOS!F15:F18) -> 0 | H9: =COUNTA(REQUISITOS!G15:G18) -> 0 | I9: =SUM(C9:H9) -> 0 | L9: =B7 -> 4. CONTEXTO DE LA ORGANIZACIÓN | M9: =B15 -> 0 | N9: =IF(M9<=24%,"INICIAL",IF(M9<=49%,"NOVATO",IF(M9<=74%,"COMPETENTE",IF(M9<=99%,"AVANZADO","EXPERTO")))) -> INICIAL
B10: 4.2 | C10: =COUNTA(REQUISITOS!B21:B25) -> 0 | D10: =COUNTA(REQUISITOS!C21:C25) -> 0 | E10: =COUNTA(REQUISITOS!D21:D25) -> 0 | F10: =COUNTA(REQUISITOS!E21:E25) -> 0 | G10: =COUNTA(REQUISITOS!F21:F25) -> 0 | H10: =COUNTA(REQUISITOS!G21:G25) -> 0 | I10: =SUM(C10:H10) -> 0 | L10: =B18 -> 5. LIDERAZGO | M10: =B25 -> 0 | N10: =IF(M10<=24%,"INICIAL",IF(M10<=49%,"NOVATO",IF(M10<=74%,"COMPETENTE",IF(M10<=99%,"AVANZADO","EXPERTO")))) -> INICIAL
B11: 4.3 | C11: =COUNTA(REQUISITOS!B28:B32) -> 0 | D11: =COUNTA(REQUISITOS!C28:C32) -> 0 | E11: =COUNTA(REQUISITOS!D28:D32) -> 0 | F11: =COUNTA(REQUISITOS!E28:E32) -> 0 | G11: =COUNTA(REQUISITOS!F28:F32) -> 0 | H11: =COUNTA(REQUISITOS!G28:G32) -> 0 | I11: =SUM(C11:H11) -> 0 | L11: =B27 -> 6. PLANIFICACIÓN | M11: =B34 -> 0 | N11: =IF(M11<=24%,"INICIAL",IF(M11<=49%,"NOVATO",IF(M11<=74%,"COMPETENTE",IF(M11<=99%,"AVANZADO","EXPERTO")))) -> INICIAL
B12: 4.4 | C12: =COUNTA(REQUISITOS!B35:B37) -> 0 | D12: =COUNTA(REQUISITOS!C35:C37) -> 0 | E12: =COUNTA(REQUISITOS!D35:D37) -> 0 | F12: =COUNTA(REQUISITOS!E35:E37) -> 0 | G12: =COUNTA(REQUISITOS!F35:F37) -> 0 | H12: =COUNTA(REQUISITOS!G35:G37) -> 0 | I12: =SUM(C12:H12) -> 0 | L12: =B36 -> 7. SOPORTE | M12: =B45 -> 0 | N12: =IF(M12<=24%,"INICIAL",IF(M12<=49%,"NOVATO",IF(M12<=74%,"COMPETENTE",IF(M12<=99%,"AVANZADO","EXPERTO")))) -> INICIAL
B13: TOTALES | C13: =SUM(C9:C12) -> 0 | D13: =SUM(D9:D12) -> 0 | E13: =SUM(E9:E12) -> 0 | F13: =SUM(F9:F12) -> 0 | G13: =SUM(G9:G12) -> 0 | H13: =SUM(H9:H12) -> 0 | I13: =SUM(I9:I12)-H13 -> 0 | L13: 8. OPERACIÓN | M13: =B53 -> 0 | N13: =IF(M13<=24%,"INICIAL",IF(M13<=49%,"NOVATO",IF(M13<=74%,"COMPETENTE",IF(M13<=99%,"AVANZADO","EXPERTO")))) -> INICIAL
B14: PORCENTAJE DE IMPLEMENTACIÓN | L14: =B55 -> 9. EVALUACIÓN DEL DESEMPEÑO | M14: =B62 -> 0 | N14: =IF(M14<=24%,"INICIAL",IF(M14<=49%,"NOVATO",IF(M14<=74%,"COMPETENTE",IF(M14<=99%,"AVANZADO","EXPERTO")))) -> INICIAL
B15: =IF(I13=0,0,((C13*C8)+(D13*D8)+(E13*E8)+(F13*F8)+(G13*G8))/I13) -> 0 | L15: =B64 -> 10. MEJORA | M15: =B70 -> 0 | N15: =IF(M15<=24%,"INICIAL",IF(M15<=49%,"NOVATO",IF(M15<=74%,"COMPETENTE",IF(M15<=99%,"AVANZADO","EXPERTO")))) -> INICIAL
L16: PORCENTAJE TOTAL DE IMPLEMENTACIÓN SGC | M16: =B77 -> 0 | N16: =IF(M16<=24%,"INICIAL",IF(M16<=49%,"NOVATO",IF(M16<=74%,"COMPETENTE",IF(M16<=99%,"AVANZADO","EXPERTO")))) -> INICIAL
L17: BRECHA | M17: =100%-M16 -> 1
B18: 5. LIDERAZGO
B19: NUMERAL | C19: 0 | D19: 0.25 | E19: 0.5 | F19: 0.75 | G19: 1 | H19: N/A | I19: TOTALES
B20: 5.1 | C20: =COUNTIF(REQUISITOS!B41:B44,"X") -> 0 | D20: =COUNTIF(REQUISITOS!C41:C44,"X") -> 0 | E20: =COUNTIF(REQUISITOS!D41:D44,"X") -> 0 | F20: =COUNTIF(REQUISITOS!E41:E44,"X") -> 0 | G20: =COUNTIF(REQUISITOS!F41:F44,"X") -> 0 | H20: =COUNTIF(REQUISITOS!G41:G44,"X") -> 0 | I20: =SUM(C20:H20) -> 0
B21: 5.2 | C21: =COUNTIF(REQUISITOS!B47:B52,"X") -> 0 | D21: =COUNTIF(REQUISITOS!C47:C52,"X") -> 0 | E21: =COUNTIF(REQUISITOS!D47:D52,"X") -> 0 | F21: =COUNTIF(REQUISITOS!E47:E52,"X") -> 0 | G21: =COUNTIF(REQUISITOS!F47:F52,"X") -> 0 | H21: =COUNTIF(REQUISITOS!G47:G52,"X") -> 0 | I21: =SUM(C21:H21) -> 0
B22: 5.3 | C22: =COUNTIF(REQUISITOS!B55:B56,"X") -> 0 | D22: =COUNTIF(REQUISITOS!C55:C56,"X") -> 0 | E22: =COUNTIF(REQUISITOS!D55:D56,"X") -> 0 | F22: =COUNTIF(REQUISITOS!E55:E56,"X") -> 0 | G22: =COUNTIF(REQUISITOS!F55:F56,"X") -> 0 | H22: =COUNTIF(REQUISITOS!G55:G56,"X") -> 0 | I22: =SUM(C22:H22) -> 0
B23: TOTALES | C23: =SUM(C20:C22) -> 0 | D23: =SUM(D20:D22) -> 0 | E23: =SUM(E20:E22) -> 0 | F23: =SUM(F20:F22) -> 0 | G23: =SUM(G20:G22) -> 0 | H23: =SUM(H20:H22) -> 0 | I23: =SUM(I20:I22)-H23 -> 0
B24: PORCENTAJE DE IMPLEMENTACIÓN
B25: =IF(I23=0,0,(C23*C19+D23*D19+E23*E19+F23*F19+G23*G19)/I23) -> 0
B27: 6. PLANIFICACIÓN
B28: NUMERAL | C28: 0 | D28: 0.25 | E28: 0.5 | F28: 0.75 | G28: 1 | H28: N/A | I28: TOTALES
B29: 6.1 | C29: =COUNTIF(REQUISITOS!B60:B75,"X") -> 0 | D29: =COUNTIF(REQUISITOS!C60:C75,"X") -> 0 | E29: =COUNTIF(REQUISITOS!D60:D75,"X") -> 0 | F29: =COUNTIF(REQUISITOS!E60:E75,"X") -> 0 | G29: =COUNTIF(REQUISITOS!F60:F75,"X") -> 0 | H29: =COUNTIF(REQUISITOS!G60:G75,"X") -> 0 | I29: =SUM(C29:H29) -> 0
B30: 6.2 | C30: =COUNTIF(REQUISITOS!B78:B82,"X") -> 0 | D30: =COUNTIF(REQUISITOS!C78:C82,"X") -> 0 | E30: =COUNTIF(REQUISITOS!D78:D82,"X") -> 0 | F30: =COUNTIF(REQUISITOS!E78:E82,"X") -> 0 | G30: =COUNTIF(REQUISITOS!F78:F82,"X") -> 0 | H30: =COUNTIF(REQUISITOS!G78:G82,"X") -> 0 | I30: =SUM(C30:H30) -> 0
B31: 6.3 | C31: =COUNTIF(REQUISITOS!B85:B87,"X") -> 0 | D31: =COUNTIF(REQUISITOS!C85:C87,"X") -> 0 | E31: =COUNTIF(REQUISITOS!D85:D87,"X") -> 0 | F31: =COUNTIF(REQUISITOS!E85:E87,"X") -> 0 | G31: =COUNTIF(REQUISITOS!F85:F87,"X") -> 0 | H31: =COUNTIF(REQUISITOS!G85:G87,"X") -> 0 | I31: =SUM(C31:H31) -> 0
B32: TOTALES | C32: =SUM(C29:C31) -> 0 | D32: =SUM(D29:D31) -> 0 | E32: =SUM(E29:E31) -> 0 | F32: =SUM(F29:F31) -> 0 | G32: =SUM(G29:G31) -> 0 | H32: =SUM(H29:H31) -> 0 | I32: =SUM(I29:I31)-H32 -> 0
B33: PORCENTAJE DE IMPLEMENTACIÓN
B34: =IF(I32=0,0,(C32*C28+D32*D28+E32*E28+F32*F28+G32*G28)/I32) -> 0
B36: 7. SOPORTE
B37: NUMERAL | C37: 0 | D37: 0.25 | E37: 0.5 | F37: 0.75 | G37: 1 | H37: N/A | I37: TOTALES
B38: 7.1 | C38: =COUNTIF(REQUISITOS!B91,"X") -> 0 | D38: =COUNTIF(REQUISITOS!C91,"X") -> 0 | E38: =COUNTIF(REQUISITOS!D91,"X") -> 0 | F38: =COUNTIF(REQUISITOS!E91,"X") -> 0 | G38: =COUNTIF(REQUISITOS!F91,"X") -> 0 | H38: =COUNTIF(REQUISITOS!G91,"X") -> 0 | I38: =SUM(C38:H38) -> 0
B39: 7.2 | C39: =COUNTIF(REQUISITOS!B94:B97,"X") -> 0 | D39: =COUNTIF(REQUISITOS!C94:C97,"X") -> 0 | E39: =COUNTIF(REQUISITOS!D94:D97,"X") -> 0 | F39: =COUNTIF(REQUISITOS!E94:E97,"X") -> 0 | G39: =COUNTIF(REQUISITOS!F94:F97,"X") -> 0 | H39: =COUNTIF(REQUISITOS!G94:G97,"X") -> 0 | I39: =SUM(C39:H39) -> 0
B40: 7.3 | C40: =COUNTIF(REQUISITOS!B100:B102,"X") -> 0 | D40: =COUNTIF(REQUISITOS!C100:C102,"X") -> 0 | E40: =COUNTIF(REQUISITOS!D100:D102,"X") -> 0 | F40: =COUNTIF(REQUISITOS!E100:E102,"X") -> 0 | G40: =COUNTIF(REQUISITOS!F100:F102,"X") -> 0 | H40: =COUNTIF(REQUISITOS!G100:G102,"X") -> 0 | I40: =SUM(C40:H40) -> 0
B41: 7.4 | C41: =COUNTIF(REQUISITOS!B105:B111,"X") -> 0 | D41: =COUNTIF(REQUISITOS!C105:C111,"X") -> 0 | E41: =COUNTIF(REQUISITOS!D105:D111,"X") -> 0 | F41: =COUNTIF(REQUISITOS!E105:E111,"X") -> 0 | G41: =COUNTIF(REQUISITOS!F105:F111,"X") -> 0 | H41: =COUNTIF(REQUISITOS!G105:G111,"X") -> 0 | I41: =SUM(C41:H41) -> 0
B42: 7.5 | C42: =COUNTIF(REQUISITOS!B114:B120,"X") -> 0 | D42: =COUNTIF(REQUISITOS!C114:C120,"X") -> 0 | E42: =COUNTIF(REQUISITOS!D114:D120,"X") -> 0 | F42: =COUNTIF(REQUISITOS!E114:E120,"X") -> 0 | G42: =COUNTIF(REQUISITOS!F114:F120,"X") -> 0 | H42: =COUNTIF(REQUISITOS!G114:G120,"X") -> 0 | I42: =SUM(C42:H42) -> 0
B43: TOTALES | C43: =SUM(C38:C42) -> 0 | D43: =SUM(D38:D42) -> 0 | E43: =SUM(E38:E42) -> 0 | F43: =SUM(F38:F42) -> 0 | G43: =SUM(G38:G42) -> 0 | H43: =SUM(H38:H42) -> 0 | I43: =SUM(I38:I42)-H43 -> 0
B44: PORCENTAJE DE IMPLEMENTACIÓN
B45: =IF(I43=0,0,(C43*C37+D43*D37+E43*E37+F43*F37+G43*G37)/I43) -> 0
B47: 8. OPERACIÓN
...

Sheet ANÁLISIS 4
B3: ANÁLISIS DE INFORMACIÓN
B5: TU NIVEL EN ÉSTA CLÁUSULA ES DE NIVEL | F5: =IF(M9<=24%,"INICIAL",IF(M9<=49%,"NOVATO",IF(M9<=74%,"COMPETENTE",IF(M9<=99%,"AVANZADO","EXPERTO")))) -> INICIAL
B9: 4. CONTEXTO DE LA ORGANIZACIÓN
C10: 0% -No documentado / No existente | D10: 25% - Aplicado / No documentado | E10: 50% - Documentado / No aplicado | F10: 75% - Aplicado y documentado | G10: 100% - Aplicado, documentado y controlado | H10: No aplica
B11: NUMERAL | C11: 0 | D11: 0.25 | E11: 0.5 | F11: 0.75 | G11: 1 | H11: N/A | I11: TOTALES
B12: 4.1 Comprensión de la organización y de su contexto | C12: =COUNTA(REQUISITOS!B15:B18) -> 0 | D12: =COUNTA(REQUISITOS!C15:C18) -> 0 | E12: =COUNTA(REQUISITOS!D15:D18) -> 0 | F12: =COUNTA(REQUISITOS!E15:E18) -> 0 | G12: =COUNTA(REQUISITOS!F15:F18) -> 0 | H12: =COUNTA(REQUISITOS!G15:G18) -> 0 | I12: =SUM(C12:G12) -> 0
B13: 4.2 Comprensión de las necesidades y expectativas de las partes interesadas | C13: =COUNTA(REQUISITOS!B21:B25) -> 0 | D13: =COUNTA(REQUISITOS!C21:C25) -> 0 | E13: =COUNTA(REQUISITOS!D21:D25) -> 0 | F13: =COUNTA(REQUISITOS!E21:E25) -> 0 | G13: =COUNTA(REQUISITOS!F21:F25) -> 0 | H13: =COUNTA(REQUISITOS!G21:G25) -> 0 | I13: =SUM(C13:H13) -> 0
B14: 4.3 Determinación del alcance del sistema de gestión ambiental | C14: =COUNTA(REQUISITOS!B28:B32) -> 0 | D14: =COUNTA(REQUISITOS!C28:C32) -> 0 | E14: =COUNTA(REQUISITOS!D28:D32) -> 0 | F14: =COUNTA(REQUISITOS!E28:E32) -> 0 | G14: =COUNTA(REQUISITOS!F28:F32) -> 0 | H14: =COUNTA(REQUISITOS!G28:G32) -> 0 | I14: =SUM(C14:H14) -> 0
B15: 4.4 Sistema de gestión ambiental | C15: =COUNTA(REQUISITOS!B35:B37) -> 0 | D15: =COUNTA(REQUISITOS!C35:C37) -> 0 | E15: =COUNTA(REQUISITOS!D35:D37) -> 0 | F15: =COUNTA(REQUISITOS!E35:E37) -> 0 | G15: =COUNTA(REQUISITOS!F35:F37) -> 0 | H15: =COUNTA(REQUISITOS!G35:G37) -> 0 | I15: =SUM(C15:H15) -> 0
B16: TOTALES | C16: =SUM(C12:C15) -> 0 | D16: =SUM(D12:D15) -> 0 | E16: =SUM(E12:E15) -> 0 | F16: =SUM(F12:F15) -> 0 | G16: =SUM(G12:G15) -> 0 | H16: =SUM(H12:H15) -> 0 | I16: =SUM(I12:I15)-H16 -> 0
B17: PORCENTAJE DE IMPLEMENTACIÓN CLÁUSULA 4
B18: =IF(I16=0,0,(C16*C11+D16*D11+E16*E11+F16*F11+G16*G11)/I16) -> 0
B40: ANÁLISIS DE INFORMACIÓN Y RECOMENDACIONES
B43: ="Según se muestra en la tabla CONTEXTO DE LA ORGANIZACIÓN el porcentaje de implementación alcanzado es de "&TEXT(B18,"0.00%")&"."&CHAR(10)&CHAR(10)&"" -> Según se muestra en la tabla CONTEXTO DE LA ORGANIZACIÓN el porcentaje de implementación alcanzado es de 0.00%.
B44: Se realiza un análisis del contexto de la organización desde un punto de vista ambiental, de igual manera las partes interesadas incluidas sus necesidades y expectativas. Determinar el alcance del SGA, así como el sistema de gestión ambiental; es decir, los procesos que serán parte de nuestro SGA

Sheet ANÁLISIS 5
B3: ANÁLISIS DE INFORMACIÓN
B5: TU NIVEL EN ÉSTA CLÁUSULA ES DE NIVEL | E5: =IF(M9<=24%,"INICIAL",IF(M9<=49%,"NOVATO",IF(M9<=74%,"COMPETENTE",IF(M9<=99%,"AVANZADO","EXPERTO")))) -> INICIAL
B9: 5. LIDERAZGO
C10: 0% -No documentado / No existente | D10: 25% - Aplicado / No documentado | E10: 50% - Documentado / No aplicado | F10: 75% - Aplicado y documentado | G10: 100% - Aplicado, documentado y controlado | H10: No aplica
B11: NUMERAL | C11: 0 | D11: 0.25 | E11: 0.5 | F11: 0.75 | G11: 1 | H11: N/A | I11: TOTALES
B12: 5.1 Liderazgo y compromiso | C12: =COUNTIF(REQUISITOS!B41:B44,"X") -> 0 | D12: =COUNTIF(REQUISITOS!C41:C44,"X") -> 0 | E12: =COUNTIF(REQUISITOS!D41:D44,"X") -> 0 | F12: =COUNTIF(REQUISITOS!E41:E44,"X") -> 0 | G12: =COUNTIF(REQUISITOS!F41:F44,"X") -> 0 | H12: =COUNTIF(REQUISITOS!G41:G44,"X") -> 0 | I12: =SUM(C12:H12) -> 0
B13: 5.2 Política ambiental | C13: =COUNTIF(REQUISITOS!B47:B52,"X") -> 0 | D13: =COUNTIF(REQUISITOS!C47:C52,"X") -> 0 | E13: =COUNTIF(REQUISITOS!D47:D52,"X") -> 0 | F13: =COUNTIF(REQUISITOS!E47:E52,"X") -> 0 | G13: =COUNTIF(REQUISITOS!F47:F52,"X") -> 0 | H13: =COUNTIF(REQUISITOS!G47:G52,"X") -> 0 | I13: =SUM(C13:H13) -> 0
B14: 5.3 Roles, responsabilidades y autoridades en la organización | C14: =COUNTIF(REQUISITOS!B55:B56,"X") -> 0 | D14: =COUNTIF(REQUISITOS!C55:C56,"X") -> 0 | E14: =COUNTIF(REQUISITOS!D55:D56,"X") -> 0 | F14: =COUNTIF(REQUISITOS!E55:E56,"X") -> 0 | G14: =COUNTIF(REQUISITOS!F55:F56,"X") -> 0 | H14: =COUNTIF(REQUISITOS!G55:G56,"X") -> 0 | I14: =SUM(C14:H14) -> 0
B15: TOTALES | C15: =SUM(C12:C14) -> 0 | D15: =SUM(D12:D14) -> 0 | E15: =SUM(E12:E14) -> 0 | F15: =SUM(F12:F14) -> 0 | G15: =SUM(G12:G14) -> 0 | H15: =SUM(H12:H14) -> 0 | I15: =SUM(I12:I14)-H15 -> 0
B16: PORCENTAJE DE IMPLEMENTACIÓN CLÁUSULA 5
B17: =IF(I15=0,0,(C15*C11+D15*D11+E15*E11+F15*F11+G15*G11)/I15) -> 0
B39: ANÁLISIS DE INFORMACIÓN Y RECOMENDACIONES
B42: ="Según se muestra en la tabla LIDERAZGO el porcentaje de implementación alcanzado es de "&TEXT(B17,"0.00%")&"" -> Según se muestra en la tabla LIDERAZGO el porcentaje de implementación alcanzado es de 0.00%
B43: Se establece, al igual que en todas las normas ISO, la importancia del involucramiento de la alta dirección para garantizar una correcta implementación, mantenimiento y mejora del SGA; además el establecimiento de la política ambiental la cuál debe de cumplir ciertos lineamientos indicados. Por último, la alta dirección también debe de garantizar que se definan y asignen los roles, responsabilidades y autoridades de la organización.

Sheet ANÁLISIS 6
B3: ANÁLISIS DE INFORMACIÓN
B5: TU NIVEL EN ÉSTA CLÁUSULA ES DE NIVEL | F5: =IF(M9<=24%,"INICIAL",IF(M9<=49%,"NOVATO",IF(M9<=74%,"COMPETENTE",IF(M9<=99%,"AVANZADO","EXPERTO")))) -> INICIAL
B9: 6. PLANIFICACION
C10: 0% -No documentado / No existente | D10: 25% - Aplicado / No documentado | E10: 50% - Documentado / No aplicado | F10: 75% - Aplicado y documentado | G10: 100% - Aplicado, documentado y controlado | H10: No aplica
B11: NUMERAL | C11: 0 | D11: 0.25 | E11: 0.5 | F11: 0.75 | G11: 1 | H11: N/A | I11: TOTALES
B12: 6.1 Acciones para abordar riesgos y oportunidades | C12: =COUNTIF(REQUISITOS!B60:B75,"X") -> 0 | D12: =COUNTIF(REQUISITOS!C60:C75,"X") -> 0 | E12: =COUNTIF(REQUISITOS!D60:D75,"X") -> 0 | F12: =COUNTIF(REQUISITOS!E60:E75,"X") -> 0 | G12: =COUNTIF(REQUISITOS!F60:F75,"X") -> 0 | H12: =COUNTIF(REQUISITOS!G60:G75,"X") -> 0 | I12: =SUM(C12:H12) -> 0
B13: 6.2 Objetivos ambientales y planificación para lograrlos | C13: =COUNTIF(REQUISITOS!B78:B82,"X") -> 0 | D13: =COUNTIF(REQUISITOS!C78:C82,"X") -> 0 | E13: =COUNTIF(REQUISITOS!D78:D82,"X") -> 0 | F13: =COUNTIF(REQUISITOS!E78:E82,"X") -> 0 | G13: =COUNTIF(REQUISITOS!F78:F82,"X") -> 0 | H13: =COUNTIF(REQUISITOS!G78:G82,"X") -> 0 | I13: =SUM(C13:H13) -> 0
B14: 6.3 Planificación de cambios | C14: =COUNTIF(REQUISITOS!B85:B87,"X") -> 0 | D14: =COUNTIF(REQUISITOS!C85:C87,"X") -> 0 | E14: =COUNTIF(REQUISITOS!D85:D87,"X") -> 0 | F14: =COUNTIF(REQUISITOS!E85:E87,"X") -> 0 | G14: =COUNTIF(REQUISITOS!F85:F87,"X") -> 0 | H14: =COUNTIF(REQUISITOS!G85:G87,"X") -> 0 | I14: =SUM(C14:H14) -> 0
B15: TOTALES | C15: =SUM(C12:C14) -> 0 | D15: =SUM(D12:D14) -> 0 | E15: =SUM(E12:E14) -> 0 | F15: =SUM(F12:F14) -> 0 | G15: =SUM(G12:G14) -> 0 | H15: =SUM(H12:H14) -> 0 | I15: =SUM(I12:I14)-H15 -> 0
B16: PORCENTAJE DE IMPLEMENTACIÓN CLÁUSULA 6
B17: =IF(I15=0,0,(C15*C11+D15*D11+E15*E11+F15*F11+G15*G11)/I15) -> 0
B43: ANÁLISIS DE INFORMACIÓN Y RECOMENDACIONES
B46: ="Según se muestra en la tabla PLANIFICACIÓN el porcentaje de implementación alcanzado es de "&TEXT(B21,"0.00%")&"" -> Según se muestra en la tabla PLANIFICACIÓN el porcentaje de implementación alcanzado es de 0.00%
B47: Éste capítulo hace referencia a la Planificación del SGA. La organización debe establecer que debe cumplir en relación a sus aspectos ambientales y requisitos legales, incluidos otros requisitos: así como los objetivos, metas y programas ambientales.

Sheet ANÁLISIS 7
B3: ANÁLISIS DE INFORMACIÓN
B5: TU NIVEL EN ÉSTA CLÁUSULA ES DE NIVEL | G5: =IF(M9<=24%,"INICIAL",IF(M9<=49%,"NOVATO",IF(M9<=74%,"COMPETENTE",IF(M9<=99%,"AVANZADO","EXPERTO")))) -> INICIAL
B9: 7.APOYO
C10: 0% -No documentado / No existente | D10: 25% - Aplicado / No documentado | E10: 50% - Documentado / No aplicado | F10: 75% - Aplicado y documentado | G10: 100% - Aplicado, documentado y controlado | H10: No aplica
B11: NUMERAL | C11: 0 | D11: 0.25 | E11: 0.5 | F11: 0.75 | G11: 1 | H11: N/A | I11: TOTALES
B12: 7.1 Recursos | C12: =COUNTIF(REQUISITOS!B91,"X") -> 0 | D12: =COUNTIF(REQUISITOS!C91,"X") -> 0 | E12: =COUNTIF(REQUISITOS!D91,"X") -> 0 | F12: =COUNTIF(REQUISITOS!E91,"X") -> 0 | G12: =COUNTIF(REQUISITOS!F91,"X") -> 0 | H12: =COUNTIF(REQUISITOS!G91,"X") -> 0 | I12: =SUM(C12:H12) -> 0
B13: 7.2 Competencia | C13: =COUNTIF(REQUISITOS!B94:B97,"X") -> 0 | D13: =COUNTIF(REQUISITOS!C94:C97,"X") -> 0 | E13: =COUNTIF(REQUISITOS!D94:D97,"X") -> 0 | F13: =COUNTIF(REQUISITOS!E94:E97,"X") -> 0 | G13: =COUNTIF(REQUISITOS!F94:F97,"X") -> 0 | H13: =COUNTIF(REQUISITOS!G94:G97,"X") -> 0 | I13: =SUM(C13:H13) -> 0
B14: 7.3 Toma de conciencia y formación | C14: =COUNTIF(REQUISITOS!B100:B102,"X") -> 0 | D14: =COUNTIF(REQUISITOS!C100:C102,"X") -> 0 | E14: =COUNTIF(REQUISITOS!D100:D102,"X") -> 0 | F14: =COUNTIF(REQUISITOS!E100:E102,"X") -> 0 | G14: =COUNTIF(REQUISITOS!F100:F102,"X") -> 0 | H14: =COUNTIF(REQUISITOS!G100:G102,"X") -> 0 | I14: =SUM(C14:H14) -> 0
B15: 7.4 Comunicación | C15: =COUNTIF(REQUISITOS!B105:B111,"X") -> 0 | D15: =COUNTIF(REQUISITOS!C105:C111,"X") -> 0 | E15: =COUNTIF(REQUISITOS!D105:D111,"X") -> 0 | F15: =COUNTIF(REQUISITOS!E105:E111,"X") -> 0 | G15: =COUNTIF(REQUISITOS!F105:F111,"X") -> 0 | H15: =COUNTIF(REQUISITOS!G105:G111,"X") -> 0 | I15: =SUM(C15:H15) -> 0
B16: 7.5 Información documentada | C16: =COUNTIF(REQUISITOS!B114:B120,"X") -> 0 | D16: =COUNTIF(REQUISITOS!C114:C120,"X") -> 0 | E16: =COUNTIF(REQUISITOS!D114:D120,"X") -> 0 | F16: =COUNTIF(REQUISITOS!E114:E120,"X") -> 0 | G16: =COUNTIF(REQUISITOS!F114:F120,"X") -> 0 | H16: =COUNTIF(REQUISITOS!G114:G120,"X") -> 0 | I16: =SUM(C16:H16) -> 0
B17: TOTALES | C17: =SUM(C12:C16) -> 0 | D17: =SUM(D12:D16) -> 0 | E17: =SUM(E12:E16) -> 0 | F17: =SUM(F12:F16) -> 0 | G17: =SUM(G12:G16) -> 0 | H17: =SUM(H12:H16) -> 0 | I17: =SUM(I12:I16)-H17 -> 0
B18: PORCENTAJE DE IMPLEMENTACIÓN CLÁUSULA 7
B19: =IF(I17=0,0,(C17*C11+D17*D11+E17*E11+F17*F11+G17*G11)/I17) -> 0
B43: ANÁLISIS DE INFORMACIÓN Y RECOMENDACIONES
B46: ="Según se muestra en la tabla APOYO el porcentaje de implementación alcanzado es de "&TEXT(B19,"0.00%")&" " -> Según se muestra en la tabla APOYO el porcentaje de implementación alcanzado es de 0.00%
B47: Toda el capítulo aborda todo el apoyo que se necesita para cumplir con nuestros objetivos de SGA, incluida la competencia que deben tener nuestros colaboradores, la toma de conciencia acerca del SGA, la comunicación tanto interna como externa y por supuesto el requisito de información documentada.

Sheet ANÁLISIS 8
B3: ANÁLISIS DE INFORMACIÓN
B5: TU NIVEL EN ÉSTA CLÁUSULA ES DE NIVEL | F5: =IF(M9<=24%,"INICIAL",IF(M9<=49%,"NOVATO",IF(M9<=74%,"COMPETENTE",IF(M9<=99%,"AVANZADO","EXPERTO")))) -> INICIAL
B8: 8. OPERACIÓN
C9: 0% -No documentado / No existente | D9: 25% - Aplicado / No documentado | E9: 50% - Documentado / No aplicado | F9: 75% - Aplicado y documentado | G9: 100% - Aplicado, documentado y controlado | H9: No aplica
B10: NUMERAL | C10: 0 | D10: 0.25 | E10: 0.5 | F10: 0.75 | G10: 1 | H10: N/A | I10: TOTALES
B11: 8.1 Planificación y control operacional | C11: =COUNTIF(REQUISITOS!B124:B130,"X") -> 0 | D11: =COUNTIF(REQUISITOS!C124:C130,"X") -> 0 | E11: =COUNTIF(REQUISITOS!D124:D130,"X") -> 0 | F11: =COUNTIF(REQUISITOS!E124:E130,"X") -> 0 | G11: =COUNTIF(REQUISITOS!F124:F130,"X") -> 0 | H11: =COUNTIF(REQUISITOS!G124:G130,"X") -> 0 | I11: =SUM(C11:H11) -> 0
B12: 8.2 Preparación y respuesta ante emergencias | C12: =COUNTIF(REQUISITOS!B133:B137,"X") -> 0 | D12: =COUNTIF(REQUISITOS!C133:C137,"X") -> 0 | E12: =COUNTIF(REQUISITOS!D133:D137,"X") -> 0 | F12: =COUNTIF(REQUISITOS!E133:E137,"X") -> 0 | G12: =COUNTIF(REQUISITOS!F133:F137,"X") -> 0 | H12: =COUNTIF(REQUISITOS!G133:G137,"X") -> 0 | I12: =SUM(C12:H12) -> 0
B13: TOTALES | C13: =SUM(C11:C12) -> 0 | D13: =SUM(D11:D12) -> 0 | E13: =SUM(E11:E12) -> 0 | F13: =SUM(F11:F12) -> 0 | G13: =SUM(G11:G12) -> 0 | H13: =SUM(H11:H12) -> 0 | I13: =SUM(I11:I12)-H13 -> 0
B14: PORCENTAJE DE IMPLEMENTACIÓN CLÁUSULA 8
B15: =IF(I13=0,0,(C13*C10+D13*D10+E13*E10+F13*F10+G13*G10)/I13) -> 0
B43: ANÁLISIS DE INFORMACIÓN Y RECOMENDACIONES
B46: ="Según se muestra en la Tabla OPERACIÓN el porcentaje de implementación alcanzado es de "&TEXT(B15,"0.00%")&"" -> Según se muestra en la Tabla OPERACIÓN el porcentaje de implementación alcanzado es de 0.00%
B47: Este capítulo describe los requisitos que la organización debe cumplir respecto al manejo de sus aspectos ambientales identificados en el capítulo 6, como determinar controles para la generación de residuos, emisiones, etc. También se contempla el tener un plan de respuestas ante posibles emergencia, es decir, se debe tener una correcta planificación además de realizar simulacros en periodos planificados.

Sheet ANÁLISIS 9
B3: ANÁLISIS DE INFORMACIÓN
B5: TU NIVEL EN ÉSTA CLÁUSULA ES DE NIVEL | G5: =IF(M9<=24%,"INICIAL",IF(M9<=49%,"NOVATO",IF(M9<=74%,"COMPETENTE",IF(M9<=99%,"AVANZADO","EXPERTO")))) -> INICIAL
B10: 9. EVALUACION DEL DESEMPEÑO
C11: 0% -No documentado / No existente | D11: 25% - Aplicado / No documentado | E11: 50% - Documentado / No aplicado | F11: 75% - Aplicado y documentado | G11: 100% - Aplicado, documentado y controlado | H11: No aplica
B12: NUMERAL | C12: 0 | D12: 0.25 | E12: 0.5 | F12: 0.75 | G12: 1 | H12: N/A | I12: TOTALES
B13: 9.1 Seguimiento, medición, análisis y evaluación | C13: =COUNTIF(REQUISITOS!B142:B152,"X") -> 0 | D13: =COUNTIF(REQUISITOS!C142:C152,"X") -> 0 | E13: =COUNTIF(REQUISITOS!D142:D152,"X") -> 0 | F13: =COUNTIF(REQUISITOS!E142:E152,"X") -> 0 | G13: =COUNTIF(REQUISITOS!F142:F152,"X") -> 0 | H13: =COUNTIF(REQUISITOS!G142:G152,"X") -> 0 | I13: =SUM(C13:H13) -> 0
B14: 9.2 Auditoría interna | C14: =COUNTIF(REQUISITOS!B156:B164,"X") -> 0 | D14: =COUNTIF(REQUISITOS!C156:C164,"X") -> 0 | E14: =COUNTIF(REQUISITOS!D156:D164,"X") -> 0 | F14: =COUNTIF(REQUISITOS!E156:E164,"X") -> 0 | G14: =COUNTIF(REQUISITOS!F156:F164,"X") -> 0 | H14: =COUNTIF(REQUISITOS!G156:G164,"X") -> 0 | I14: =SUM(C14:H14) -> 0
B15: 9.3 Revisión por la dirección | C15: =COUNTIF(REQUISITOS!B168:B180,"X") -> 0 | D15: =COUNTIF(REQUISITOS!C168:C180,"X") -> 0 | E15: =COUNTIF(REQUISITOS!D168:D180,"X") -> 0 | F15: =COUNTIF(REQUISITOS!E168:E180,"X") -> 0 | G15: =COUNTIF(REQUISITOS!F168:F180,"X") -> 0 | H15: =COUNTIF(REQUISITOS!G168:G180,"X") -> 0 | I15: =SUM(C15:H15) -> 0
B16: TOTALES | C16: =SUM(C13:C15) -> 0 | D16: =SUM(D13:D15) -> 0 | E16: =SUM(E13:E15) -> 0 | F16: =SUM(F13:F15) -> 0 | G16: =SUM(G13:G15) -> 0 | H16: =SUM(H13:H15) -> 0 | I16: =SUM(I13:I15)-H16 -> 0
B17: PORCENTAJE DE IMPLEMENTACIÓN CLÁUSULA 9
B18: =IF(I16=0,0,(C16*C12+D16*D12+E16*E12+F16*F12+G16*G12)/I16) -> 0
B42: ANÁLISIS DE INFORMACIÓN Y RECOMENDACIONES
B45: ="Según se muestra en la Tabla Evaluación del Desempeño el porcentaje de implementación alcanzado es de "&TEXT(B18,"0.00%")&" " -> Según se muestra en la Tabla Evaluación del Desempeño el porcentaje de implementación alcanzado es de 0.00%
B46: En este capítulo se define las actividades necesarias para verificar los resultados de nuestro SGA, estableciendo todo aquello que necesita ser medido como indicadores, evaluar el cumplimiento de nuestros requisitos legales, y dos métodos adicionales que sirven también para concoer el estado de nuestro SGA que es la auditoría interna y revisión por la dirección.

Sheet ANÁLISIS 10
B3: ANÁLISIS DE INFORMACIÓN
B5: TU NIVEL EN ÉSTA CLÁUSULA ES DE NIVEL | H5: =IF(M9<=24%,"INICIAL",IF(M9<=49%,"NOVATO",IF(M9<=74%,"COMPETENTE",IF(M9<=99%,"AVANZADO","EXPERTO")))) -> INICIAL
B9: 10. MEJORA
C10: 0% -No documentado / No existente | D10: 25% - Aplicado / No documentado | E10: 50% - Documentado / No aplicado | F10: 75% - Aplicado y documentado | G10: 100% - Aplicado, documentado y controlado | H10: No aplica
B11: NUMERAL | C11: 0 | D11: 0.25 | E11: 0.5 | F11: 0.75 | G11: 1 | H11: N/A | I11: TOTALES
B12: 10.1 Generalidades | C12: =COUNTIF(REQUISITOS!B184:B185,"X") -> 0 | D12: =COUNTIF(REQUISITOS!C184:C185,"X") -> 0 | E12: =COUNTIF(REQUISITOS!D184:D185,"X") -> 0 | F12: =COUNTIF(REQUISITOS!E184:E185,"X") -> 0 | G12: =COUNTIF(REQUISITOS!F184:F185,"X") -> 0 | H12: =COUNTIF(REQUISITOS!G184:G185,"X") -> 0 | I12: =SUM(C12:H12) -> 0
B13: 10.2 No conformidad y acción correctiva | C13: =COUNTIF(REQUISITOS!B188:B193,"X") -> 0 | D13: =COUNTIF(REQUISITOS!C188:C193,"X") -> 0 | E13: =COUNTIF(REQUISITOS!D188:D193,"X") -> 0 | F13: =COUNTIF(REQUISITOS!E188:E193,"X") -> 0 | G13: =COUNTIF(REQUISITOS!F188:F193,"X") -> 0 | H13: =COUNTIF(REQUISITOS!G188:G193,"X") -> 0 | I13: =SUM(C13:H13) -> 0
B14: TOTALES | C14: =SUM(C12:C13) -> 0 | D14: =SUM(D12:D13) -> 0 | E14: =SUM(E12:E13) -> 0 | F14: =SUM(F12:F13) -> 0 | G14: =SUM(G12:G13) -> 0 | H14: =SUM(H12:H13) -> 0 | I14: =SUM(I12:I13)-H14 -> 0
B15: PORCENTAJE DE IMPLEMENTACIÓN CLÁUSULA 10
B16: =IF(I14=0,0,(C14*C11+D14*D11+E14*E11+F14*F11+G14*G11)/I14) -> 0
B42: ANÁLISIS DE INFORMACIÓN Y RECOMENDACIONES
B45: ="Según se muestra en la Tabla MEJORA el porcentaje de implementación alcanzado es de "&TEXT(B16,"0.00%")&" " -> Según se muestra en la Tabla MEJORA el porcentaje de implementación alcanzado es de 0.00%
B46: Está relacionado con la mejora del propio sistema y del comportamiento ambiental. En base a los resultados de verificación y al desempeño de los procesos se deberán emprender las no conformidades y acciones correctivas oportunas.
